<?xml version="1.0" encoding="utf-8"?>
<!-- This URDF was automatically created by SolidWorks to URDF Exporter! Originally created by Stephen Brawner (brawner@gmail.com) 
     Commit Version: 1.5.1-0-g916b5db  Build Version: 1.5.7152.31018
     For more information, please see http://wiki.ros.org/sw_urdf_exporter -->
<robot
  name="Анимация тест (негробот)">
  <link
    name="base_link">
    <inertial>
      <origin
        xyz="0.046613 0.012157 -0.17439"
        rpy="0 0 0" />
      <mass
        value="0.0011973" />
      <inertia
        ixx="2.7785E-08"
        ixy="-1.8627E-11"
        ixz="1.1961E-11"
        iyy="2.7776E-08"
        iyz="-9.586E-12"
        izz="4.9948E-08" />
    </inertial>
    <visual>
      <origin
        xyz="0 0 0"
        rpy="0 0 0" />
      <geometry>
        <mesh
          filename="package://Анимация тест (негробот)/meshes/base_link.STL" />
      </geometry>
      <material
        name="">
        <color
          rgba="0.79216 0.81961 0.93333 1" />
      </material>
    </visual>
    <collision>
      <origin
        xyz="0 0 0"
        rpy="0 0 0" />
      <geometry>
        <mesh
          filename="package://Анимация тест (негробот)/meshes/base_link.STL" />
      </geometry>
    </collision>
  </link>
  <link
    name="frontleftwheel_Link">
    <inertial>
      <origin
        xyz="0 0.036801 0"
        rpy="0 0 0" />
      <mass
        value="0.034365" />
      <inertia
        ixx="1.0832E-05"
        ixy="-1.3066E-21"
        ixz="1.6941E-21"
        iyy="1.9957E-05"
        iyz="-1.0499E-21"
        izz="1.0832E-05" />
    </inertial>
    <visual>
      <origin
        xyz="0 0 0"
        rpy="0 0 0" />
      <geometry>
        <mesh
          filename="package://Анимация тест (негробот)/meshes/frontleftwheel_Link.STL" />
      </geometry>
      <material
        name="">
        <color
          rgba="0.79216 0.81961 0.93333 1" />
      </material>
    </visual>
    <collision>
      <origin
        xyz="0 0 0"
        rpy="0 0 0" />
      <geometry>
        <mesh
          filename="package://Анимация тест (негробот)/meshes/frontleftwheel_Link.STL" />
      </geometry>
    </collision>
  </link>
  <joint
    name="frontleftwheel_joint"
    type="continuous">
    <origin
      xyz="0.11412 0.14843 0.009649"
      rpy="0 0.57633 0" />
    <parent
      link="base_link" />
    <child
      link="frontleftwheel_Link" />
    <axis
      xyz="0 1 0" />
  </joint>
  <link
    name="reartleftwheel_Link">
    <inertial>
      <origin
        xyz="0 0 0"
        rpy="0 0 0" />
      <mass
        value="0.034365" />
      <inertia
        ixx="0"
        ixy="0"
        ixz="0"
        iyy="0"
        iyz="0"
        izz="0" />
    </inertial>
    <visual>
      <origin
        xyz="0 0 0"
        rpy="0 0 0" />
      <geometry>
        <mesh
          filename="package://Анимация тест (негробот)/meshes/reartleftwheel_Link.STL" />
      </geometry>
      <material
        name="">
        <color
          rgba="1 1 1 1" />
      </material>
    </visual>
    <collision>
      <origin
        xyz="0 0 0"
        rpy="0 0 0" />
      <geometry>
        <mesh
          filename="package://Анимация тест (негробот)/meshes/reartleftwheel_Link.STL" />
      </geometry>
    </collision>
  </link>
  <joint
    name="reartleftwheel_Joint"
    type="continuous">
    <origin
      xyz="-0.020877 0.14843 0.009649"
      rpy="0 -0.68995 0" />
    <parent
      link="base_link" />
    <child
      link="reartleftwheel_Link" />
    <axis
      xyz="0 1 0" />
  </joint>
</robot>